Workbook

Sheet ①前提条件
A1: MIGAKI BASE｜月次損益シミュレーション 前提条件
A2: 青字セルが入力値（変更可）。黒字セルは計算式。2026-04-05版
A3: 項目 | B3: 設定値 | C3: 単位 | D3: 備考・出典
A4: A｜価格設定
A5: 1泊あたり単価（保守シナリオ） | B5: 50000 | C5: 円/泊 | D5: 浮遊のいえ（上越市）4名1泊4万円を基準に設定
A6: 1泊あたり単価（標準シナリオ） | B6: 65000 | C6: 円/泊 | D6: Luxury Dojo差別化・インバウンド高単価
A7: 1泊あたり単価（楽観シナリオ） | B7: 85000 | C7: 円/泊 | D7: スーパーホスト取得後・リピーター多数
A8: OTA手数料率（Airbnb等） | B8: 0.15 | C8: % | D8: Airbnb標準。Booking.comは15〜18%
A9: 直接予約割合 | B9: 0.1 | C9: % | D9: MIGAKI道場員・リピーターからの直予約想定
A10: 手取り単価（OTA手数料控除後・標準） | B10: =B6*(1-B7) -> -5524935000 | C10: 円/泊 | D10: B6 x (1 - OTA手数料率)
A11: B｜月別稼働率（季節性）
A12: 1月 | B12: 0.6 | C12: % | D12: 冬スキーシーズン最盛期
A13: 2月 | B13: 0.65 | C13: % | D13: スキー・祝日
A14: 3月 | B14: 0.35 | C14: % | D14: 春休み・雪解け
A15: 4月 | B15: 0.25 | C15: % | D15: 閑散期
A16: 5月 | B16: 0.2 | C16: % | D16: 閑散期
A17: 6月 | B17: 0.2 | C17: % | D17: 閑散期
A18: 7月 | B18: 0.4 | C18: % | D18: 夏合宿・お盆
A19: 8月 | B19: 0.45 | C19: % | D19: 夏合宿・お盆ピーク
A20: 9月 | B20: 0.25 | C20: % | D20: 閑散期
A21: 10月 | B21: 0.2 | C21: % | D21: 紅葉・ライダー
A22: 11月 | B22: 0.25 | C22: % | D22: 閑散期
A23: 12月 | B23: 0.55 | C23: % | D23: スキー開幕・年末
A24: 年間平均稼働率 | B24: =AVERAGE(B12:B23) -> 0.3625 | C24: % | D24: 計算値
A25: C｜月次固定費
A26: 両親への固定報酬 | B26: 50000 | C26: 円/月 | D26: チェックイン・庭管理・緊急対応。目安：月5万円固定
A27: 光熱費（冬季は増加想定） | B27: 40000 | C27: 円/月 | D27: 冬季は+2万円。月次シートで季節調整
A28: 融資返済 | B28: 15000 | C28: 円/月 | D28: 50万円・3年返済・月15,000円
A29: 通信費・ソフトウェア費 | B29: 7000 | C29: 円/月 | D29: Claude・予約管理・Wi-Fi等
A30: 固定資産税等（月割） | B30: 8333 | C30: 円/月 | D30: 年間10万円÷12ヶ月
A31: 清掃外注費（シルバー等） | B31: 20000 | C31: 円/月 | D31: 繁忙期はスポット追加。閑散期は0
A32: 月次固定費 合計 | B32: =SUM(B26:B31) -> 140333 | C32: 円/月 | D32: 計算値（損益分岐点の基準）
A33: D｜サブ収益（MIGAKI道場・コンテンツ）
A34: MIGAKI道場員数（白帯・500円） | B34: 20 | C34: 人 | D34: 1年目の想定
A35: MIGAKI道場員数（青帯・980円） | B35: 15 | C35: 人 | D35: 1年目の想定
A36: MIGAKI道場員数（黒帯・3,000円） | B36: 5 | C36: 人 | D36: 1年目の想定
A37: note・アフィリエイト収入 | B37: 30000 | C37: 円/月 | D37: 現状規模から継続
A38: 道場メンバーシップ月次収益 | B38: =B34*500+B35*980+B36*3000 -> 39700 | C38: 円/月 | D38: 計算値
A39: サブ収益 月次合計 | B39: =B38+B37 -> 69700 | C39: 円/月 | D39: 道場収益＋note収益
A40: E｜両親への歩合報酬
...

Sheet ②月次損益（標準）
A1: MIGAKI BASE｜月次損益シミュレーション（標準シナリオ）
A2: 青字＝前提条件シートからの参照 黒字＝計算式 ※前提条件シートの入力値を変更すると自動更新されます
A3: 項目 | B3: 1月 | C3: 2月 | D3: 3月 | E3: 4月 | F3: 5月 | G3: 6月 | H3: 7月 | I3: 8月 | J3: 9月 | K3: 10月 | L3: 11月 | M3: 12月 | N3: 年間合計
A4: 稼働率 | B4: ='①前提条件'!B12 -> 0.6 | C4: ='①前提条件'!B13 -> 0.65 | D4: ='①前提条件'!B14 -> 0.35 | E4: ='①前提条件'!B15 -> 0.25 | F4: ='①前提条件'!B16 -> 0.2 | G4: ='①前提条件'!B17 -> 0.2 | H4: ='①前提条件'!B18 -> 0.4 | I4: ='①前提条件'!B19 -> 0.45 | J4: ='①前提条件'!B20 -> 0.25 | K4: ='①前提条件'!B21 -> 0.2 | L4: ='①前提条件'!B22 -> 0.25 | M4: ='①前提条件'!B23 -> 0.55 | N4: =AVERAGE(B4:M4) -> 0.3625
A5: 稼働泊数（日） | B5: =ROUND(B4*31,0) -> 19 | C5: =ROUND(C4*31,0) -> 20 | D5: =ROUND(D4*31,0) -> 11 | E5: =ROUND(E4*31,0) -> 8 | F5: =ROUND(F4*31,0) -> 6 | G5: =ROUND(G4*31,0) -> 6 | H5: =ROUND(H4*31,0) -> 12 | I5: =ROUND(I4*31,0) -> 14 | ... M5: =ROUND(M4*31,0) -> 17 | N5: =SUM(B5:M5) -> 135
A6: 宿泊売上（OTA経由・手取り） | B6: =B5*(1-'①前提条件'!B8)*'①前提条件'!B9 -> 1.615 | C6: =C5*(1-'①前提条件'!B8)*'①前提条件'!B9 -> 1.7 | D6: =D5*(1-'①前提条件'!B8)*'①前提条件'!B9 -> 0.935 | E6: =E5*(1-'①前提条件'!B8)*'①前提条件'!B9 -> 0.68 | F6: =F5*(1-'①前提条件'!B8)*'①前提条件'!B9 -> 0.51 | G6: =G5*(1-'①前提条件'!B8)*'①前提条件'!B9 -> 0.51 | H6: =H5*(1-'①前提条件'!B8)*'①前提条件'!B9 -> 1.02 | I6: =I5*(1-'①前提条件'!B8)*'①前提条件'!B9 -> 1.19 | J6: =J5*(1-'①前提条件'!B8)*'①前提条件'!B9 -> 0.68 | K6: =K5*(1-'①前提条件'!B8)*'①前提条件'!B9 -> 0.51 | L6: =L5*(1-'①前提条件'!B8)*'①前提条件'!B9 -> 0.68 | M6: =M5*(1-'①前提条件'!B8)*'①前提条件'!B9 -> 1.445 | N6: =SUM(B6:M6) -> 11.475
A7: 宿泊売上（直接予約・手取り） | B7: =B5*'①前提条件'!B8*'①前提条件'!B6 -> 185250 | C7: =C5*'①前提条件'!B8*'①前提条件'!B6 -> 195000 | D7: =D5*'①前提条件'!B8*'①前提条件'!B6 -> 107250 | E7: =E5*'①前提条件'!B8*'①前提条件'!B6 -> 78000 | F7: =F5*'①前提条件'!B8*'①前提条件'!B6 -> 58500 | G7: =G5*'①前提条件'!B8*'①前提条件'!B6 -> 58500 | H7: =H5*'①前提条件'!B8*'①前提条件'!B6 -> 117000 | I7: =I5*'①前提条件'!B8*'①前提条件'!B6 -> 136500 | J7: =J5*'①前提条件'!B8*'①前提条件'!B6 -> 78000 | K7: =K5*'①前提条件'!B8*'①前提条件'!B6 -> 58500 | L7: =L5*'①前提条件'!B8*'①前提条件'!B6 -> 78000 | M7: =M5*'①前提条件'!B8*'①前提条件'!B6 -> 165750 | N7: =SUM(B7:M7) -> 1316250
A8: 宿泊売上 合計 | B8: =B6+B7 -> 185251.61 | C8: =C6+C7 -> 195001.7 | D8: =D6+D7 -> 107250.93 | E8: =E6+E7 -> 78000.68 | F8: =F6+F7 -> 58500.51 | G8: =G6+G7 -> 58500.51 | H8: =H6+H7 -> 117001.02 | I8: =I6+I7 -> 136501.19 | ... M8: =M6+M7 -> 165751.45 | N8: =SUM(B8:M8) -> 1316261.5
A10: サブ収益（道場＋note） | B10: ='①前提条件'!B39 -> 69700 | C10: ='①前提条件'!B39 -> 69700 | D10: ='①前提条件'!B39 -> 69700 | E10: ='①前提条件'!B39 -> 69700 | F10: ='①前提条件'!B39 -> 69700 | G10: ='①前提条件'!B39 -> 69700 | H10: ='①前提条件'!B39 -> 69700 | I10: ='①前提条件'!B39 -> 69700 | J10: ='①前提条件'!B39 -> 69700 | K10: ='①前提条件'!B39 -> 69700 | L10: ='①前提条件'!B39 -> 69700 | M10: ='①前提条件'!B39 -> 69700 | N10: =SUM(B10:M10) -> 836400
A11: ▶ 売上合計 | B11: =B8+B10 -> 254951.61 | C11: =C8+C10 -> 264701.7 | D11: =D8+D10 -> 176950.93 | E11: =E8+E10 -> 147700.68 | F11: =F8+F10 -> 128200.51 | G11: =G8+G10 -> 128200.51 | H11: =H8+H10 -> 186701.02 | I11: =I8+I10 -> 206201.19 | ... M11: =M8+M10 -> 235451.45 | N11: =SUM(B11:M11) -> 2152661.5
A13: 【変動費】
A14: OTA手数料 | B14: =B5*(1-'①前提条件'!B8)*'①前提条件'!B6*'①前提条件'!B7 -> 89228750000 | C14: =C5*(1-'①前提条件'!B8)*'①前提条件'!B6*'①前提条件'!B7 -> 93925000000 | D14: =D5*(1-'①前提条件'!B8)*'①前提条件'!B6*'①前提条件'!B7 -> 51658750000 | E14: =E5*(1-'①前提条件'!B8)*'①前提条件'!B6*'①前提条件'!B7 -> 37570000000 | F14: =F5*(1-'①前提条件'!B8)*'①前提条件'!B6*'①前提条件'!B7 -> 28177500000 | G14: =G5*(1-'①前提条件'!B8)*'①前提条件'!B6*'①前提条件'!B7 -> 28177500000 | H14: =H5*(1-'①前提条件'!B8)*'①前提条件'!B6*'①前提条件'!B7 -> 56355000000 | I14: =I5*(1-'①前提条件'!B8)*'①前提条件'!B6*'①前提条件'!B7 -> 65747500000 | J14: =J5*(1-'①前提条件'!B8)*'①前提条件'!B6*'①前提条件'!B7 -> 37570000000 | K14: =K5*(1-'①前提条件'!B8)*'①前提条件'!B6*'①前提条件'!B7 -> 28177500000 | L14: =L5*(1-'①前提条件'!B8)*'①前提条件'!B6*'①前提条件'!B7 -> 37570000000 | M14: =M5*(1-'①前提条件'!B8)*'①前提条件'!B6*'①前提条件'!B7 -> 79836250000 | N14: =SUM(B14:M14) -> 633993750000
A15: 両親歩合報酬 | B15: =B5*'①前提条件'!B41 -> 9500 | C15: =C5*'①前提条件'!B41 -> 10000 | D15: =D5*'①前提条件'!B41 -> 5500 | E15: =E5*'①前提条件'!B41 -> 4000 | F15: =F5*'①前提条件'!B41 -> 3000 | G15: =G5*'①前提条件'!B41 -> 3000 | H15: =H5*'①前提条件'!B41 -> 6000 | I15: =I5*'①前提条件'!B41 -> 7000 | J15: =J5*'①前提条件'!B41 -> 4000 | K15: =K5*'①前提条件'!B41 -> 3000 | L15: =L5*'①前提条件'!B41 -> 4000 | M15: =M5*'①前提条件'!B41 -> 8500 | N15: =SUM(B15:M15) -> 67500
A16: 変動費 合計 | B16: =B14+B15 -> 89228759500 | C16: =C14+C15 -> 93925010000 | D16: =D14+D15 -> 51658755500 | E16: =E14+E15 -> 37570004000 | F16: =F14+F15 -> 28177503000 | G16: =G14+G15 -> 28177503000 | H16: =H14+H15 -> 56355006000 | I16: =I14+I15 -> 65747507000 | ... M16: =M14+M15 -> 79836258500 | N16: =SUM(B16:M16) -> 633993817500
A18: 【固定費】
A19: 両親固定報酬 | B19: ='①前提条件'!B26 -> 50000 | C19: ='①前提条件'!B26 -> 50000 | D19: ='①前提条件'!B26 -> 50000 | E19: ='①前提条件'!B26 -> 50000 | F19: ='①前提条件'!B26 -> 50000 | G19: ='①前提条件'!B26 -> 50000 | H19: ='①前提条件'!B26 -> 50000 | I19: ='①前提条件'!B26 -> 50000 | J19: ='①前提条件'!B26 -> 50000 | K19: ='①前提条件'!B26 -> 50000 | L19: ='①前提条件'!B26 -> 50000 | M19: ='①前提条件'!B26 -> 50000 | N19: =SUM(B19:M19) -> 600000
A20: 光熱費（冬季調整込） | B20: ='①前提条件'!B27+20000 -> 60000 | C20: ='①前提条件'!B27+20000 -> 60000 | D20: ='①前提条件'!B27 -> 40000 | E20: ='①前提条件'!B27 -> 40000 | F20: ='①前提条件'!B27 -> 40000 | G20: ='①前提条件'!B27 -> 40000 | H20: ='①前提条件'!B27 -> 40000 | I20: ='①前提条件'!B27 -> 40000 | J20: ='①前提条件'!B27 -> 40000 | K20: ='①前提条件'!B27 -> 40000 | L20: ='①前提条件'!B27 -> 40000 | M20: ='①前提条件'!B27+20000 -> 60000 | N20: =SUM(B20:M20) -> 540000
A21: 融資返済 | B21: ='①前提条件'!B28 -> 15000 | C21: ='①前提条件'!B28 -> 15000 | D21: ='①前提条件'!B28 -> 15000 | E21: ='①前提条件'!B28 -> 15000 | F21: ='①前提条件'!B28 -> 15000 | G21: ='①前提条件'!B28 -> 15000 | H21: ='①前提条件'!B28 -> 15000 | I21: ='①前提条件'!B28 -> 15000 | J21: ='①前提条件'!B28 -> 15000 | K21: ='①前提条件'!B28 -> 15000 | L21: ='①前提条件'!B28 -> 15000 | M21: ='①前提条件'!B28 -> 15000 | N21: =SUM(B21:M21) -> 180000
A22: 通信費・ソフトウェア | B22: ='①前提条件'!B29 -> 7000 | C22: ='①前提条件'!B29 -> 7000 | D22: ='①前提条件'!B29 -> 7000 | E22: ='①前提条件'!B29 -> 7000 | F22: ='①前提条件'!B29 -> 7000 | G22: ='①前提条件'!B29 -> 7000 | H22: ='①前提条件'!B29 -> 7000 | I22: ='①前提条件'!B29 -> 7000 | J22: ='①前提条件'!B29 -> 7000 | K22: ='①前提条件'!B29 -> 7000 | L22: ='①前提条件'!B29 -> 7000 | M22: ='①前提条件'!B29 -> 7000 | N22: =SUM(B22:M22) -> 84000
A23: 固定資産税等（月割） | B23: ='①前提条件'!B30 -> 8333 | C23: ='①前提条件'!B30 -> 8333 | D23: ='①前提条件'!B30 -> 8333 | E23: ='①前提条件'!B30 -> 8333 | F23: ='①前提条件'!B30 -> 8333 | G23: ='①前提条件'!B30 -> 8333 | H23: ='①前提条件'!B30 -> 8333 | I23: ='①前提条件'!B30 -> 8333 | J23: ='①前提条件'!B30 -> 8333 | K23: ='①前提条件'!B30 -> 8333 | L23: ='①前提条件'!B30 -> 8333 | M23: ='①前提条件'!B30 -> 8333 | N23: =SUM(B23:M23) -> 99996
A24: 清掃外注費 | B24: ='①前提条件'!B31 -> 20000 | C24: ='①前提条件'!B31 -> 20000 | D24: ='①前提条件'!B31 -> 20000 | E24: ='①前提条件'!B31 -> 20000 | F24: ='①前提条件'!B31 -> 20000 | G24: ='①前提条件'!B31 -> 20000 | H24: ='①前提条件'!B31 -> 20000 | I24: ='①前提条件'!B31 -> 20000 | J24: ='①前提条件'!B31 -> 20000 | K24: ='①前提条件'!B31 -> 20000 | L24: ='①前提条件'!B31 -> 20000 | M24: ='①前提条件'!B31 -> 20000 | N24: =SUM(B24:M24) -> 240000
A25: 固定費 合計 | B25: =B19+B20+B21+B22+B23+B24 -> 160333 | C25: =C19+C20+C21+C22+C23+C24 -> 160333 | D25: =D19+D20+D21+D22+D23+D24 -> 140333 | E25: =E19+E20+E21+E22+E23+E24 -> 140333 | F25: =F19+F20+F21+F22+F23+F24 -> 140333 | G25: =G19+G20+G21+G22+G23+G24 -> 140333 | H25: =H19+H20+H21+H22+H23+H24 -> 140333 | I25: =I19+I20+I21+I22+I23+I24 -> 140333 | ... M25: =M19+M20+M21+M22+M23+M24 -> 160333 | N25: =SUM(B25:M25) -> 1743996
A27: 費用 合計 | B27: =B16+B25 -> 89228919833 | C27: =C16+C25 -> 93925170333 | D27: =D16+D25 -> 51658895833 | E27: =E16+E25 -> 37570144333 | F27: =F16+F25 -> 28177643333 | G27: =G16+G25 -> 28177643333 | H27: =H16+H25 -> 56355146333 | I27: =I16+I25 -> 65747647333 | ... M27: =M16+M25 -> 79836418833 | N27: =SUM(B27:M27) -> 633995561496
A28: ▶ 月次損益 | B28: =B11-B27 -> -8.9228665e+10 | C28: =C11-C27 -> -9.3924906e+10 | D28: =D11-D27 -> -5.1658719e+10 | E28: =E11-E27 -> -3.7569997e+10 | F28: =F11-F27 -> -2.8177515e+10 | G28: =G11-G27 -> -2.8177515e+10 | H28: =H11-H27 -> -5.635496e+10 | I28: =I11-I27 -> -6.5747441e+10 | ... M28: =M11-M27 -> -7.9836183e+10 | N28: =SUM(B28:M28) -> -6.3399341e+11
A29: ▶ 累計損益 | B29: =B28 -> -8.9228665e+10 | C29: =B29+C28 -> -1.8315357e+11 | D29: =C29+D28 -> -2.3481229e+11 | E29: =D29+E28 -> -2.7238229e+11 | F29: =E29+F28 -> -3.005598e+11 | G29: =F29+G28 -> -3.2873732e+11 | H29: =G29+H28 -> -3.8509228e+11 | I29: =H29+I28 -> -4.5083972e+11 | J29: =I29+J28 -> -4.8840971e+11 | ... M29: =L29+M28 -> -6.3399341e+11 | N29: =M29 -> -6.3399341e+11

Sheet ③損益分岐点&シナリオ
A1: MIGAKI BASE｜損益分岐点分析 & シナリオ比較
A2: 分析項目 | B2: 保守シナリオ | C2: 標準シナリオ | D2: 楽観シナリオ | E2: 備考
A3: 1泊あたり単価 | B3: ='①前提条件'!B5 -> 50000 | C3: ='①前提条件'!B6 -> 65000 | D3: ='①前提条件'!B7 -> 85000 | E3: 前提条件シートから参照
A4: OTA手数料控除後の手取り単価 | B4: ='①前提条件'!B5*(1-'①前提条件'!B7) -> -4249950000 | C4: ='①前提条件'!B9 -> 0.1 | D4: ='①前提条件'!B7*(1-'①前提条件'!B7) -> -7224915000 | E4: OTA手数料15%控除後
A5: 月次固定費（合計） | B5: ='①前提条件'!B32 -> 140333 | C5: ='①前提条件'!B32 -> 140333 | D5: ='①前提条件'!B32 -> 140333 | E5: 前提条件シートから参照
A6: 損益分岐点（泊数/月） | B6: =CEILING(B5/B4,1) -> 0 | C6: =CEILING(C5/C4,1) -> 1403330 | D6: =CEILING(D5/D4,1) -> 0 | E6: この泊数を超えると固定費回収
A7: 損益分岐点（稼働率換算） | B7: =B6/31 -> 0 | C7: =C6/31 -> 45268.71 | D7: =D6/31 -> 0 | E7: 損益分岐点泊数÷31日
A9: 年間収益予測（稼働率別）
A10: 稼働率 | B10: 保守（5万円/泊） | C10: 標準（6.5万円/泊） | D10: 楽観（8.5万円/泊） | E10: 備考
A11: 0.2 | B11: =A11*365*'①前提条件'!B5*(1-'①前提条件'!B7) -> -310246350000 | C11: =A11*365*'①前提条件'!B6*(1-'①前提条件'!B7)+('①前提条件'!B39*12) -> -403319418600 | D11: =A11*365*'①前提条件'!B7*(1-'①前提条件'!B7) -> -527418795000 | E11: 閑散期水準
A12: 0.3 | B12: =A12*365*'①前提条件'!B5*(1-'①前提条件'!B7) -> -465369525000 | C12: =A12*365*'①前提条件'!B6*(1-'①前提条件'!B7)+('①前提条件'!B39*12) -> -604979546100 | D12: =A12*365*'①前提条件'!B7*(1-'①前提条件'!B7) -> -791128192500 | E12: 1年目目標
A13: 0.4 | B13: =A13*365*'①前提条件'!B5*(1-'①前提条件'!B7) -> -620492700000 | C13: =A13*365*'①前提条件'!B6*(1-'①前提条件'!B7)+('①前提条件'!B39*12) -> -806639673600 | D13: =A13*365*'①前提条件'!B7*(1-'①前提条件'!B7) -> -1054837590000 | E13: 2年目目標
A14: 0.55 | B14: =A14*365*'①前提条件'!B5*(1-'①前提条件'!B7) -> -853177462500 | C14: =A14*365*'①前提条件'!B6*(1-'①前提条件'!B7)+('①前提条件'!B39*12) -> -1109129864850 | D14: =A14*365*'①前提条件'!B7*(1-'①前提条件'!B7) -> -1450401686250 | E14: 標準シナリオ
A15: 0.65 | B15: =A15*365*'①前提条件'!B5*(1-'①前提条件'!B7) -> -1008300637500 | C15: =A15*365*'①前提条件'!B6*(1-'①前提条件'!B7)+('①前提条件'!B39*12) -> -1310789992350 | D15: =A15*365*'①前提条件'!B7*(1-'①前提条件'!B7) -> -1714111083750 | E15: スーパーホスト後
A16: 0.7 | B16: =A16*365*'①前提条件'!B5*(1-'①前提条件'!B7) -> -1085862225000 | C16: =A16*365*'①前提条件'!B6*(1-'①前提条件'!B7)+('①前提条件'!B39*12) -> -1411620056100 | D16: =A16*365*'①前提条件'!B7*(1-'①前提条件'!B7) -> -1845965782500 | E16: 楽観シナリオ
A18: ROI試算（投資対効果）
A19: 投資項目 | B19: 投資額 | C19: 年間削減/増収効果 | D19: 回収期間 | E19: 備考
A20: 内窓設置（断熱改修） | B20: 500000 | C20: 360000 | D20: =B20/C20 -> 1.3888889 | E20: 暖房費月3万円削減×12ヶ月。省エネ補助30万適用後は回収がさらに短縮
A21: キッチンリノベ | B21: 800000 | C21: 1200000 | D21: =B21/C21 -> 0.66666667 | E21: 高単価（+2万円/泊）×60泊/年の想定増収。持続化補助2/3適用後は実質負担267万
A22: スマートロック導入 | B22: 80000 | C22: 600000 | D22: =B22/C22 -> 0.13333333 | E22: 両親の現地拘束ゼロ化・自動チェックイン。人件費的価値換算
A23: Airbnbアカウント先行開設 | B23: 0 | C23: 200000 | D23: =B23/C23 -> 0 | E23: ブースト期間（初期20予約）の早期獲得価値。コストゼロ
A25: LTV（顧客生涯価値）試算
A26: 項目 | B26: 設定値 | C26: 計算結果 | E26: 備考
A27: 平均宿泊単価 | B27: 65000 | E27: 標準シナリオ
A28: 年間訪問回数（推定） | B28: 1.5 | E28: 1年目:1回、2年目以降:2回想定の平均
A29: リピート継続年数 | B29: 5 | E29: ブランドロイヤルティ向上想定
A30: LTV（1ゲスト） | C30: =B27*B28*B29 -> 487500 | E30: 年間単価×訪問回数×継続年数
A31: MIGAKI道場員LTV（黒帯・36ヶ月） | B31: 3000 | C31: =B31*36 -> 108000 | E31: 月3,000円×36ヶ月
